Workbook
Name MRI: 'Drop Down List'!$E$31:$F$44

Sheet Drop Down List
A1: DROP DOWN VALUES
A2: EMP STATUS | B2: REGULAR | D2: FREQUENCY | E2: ANNUAL | F2: ANN
B3: REGULAR SECONDED | E3: BI-MONTHLY | F3: BIM
B4: PROBATIONARY | E4: BI-WEEKLY | F4: NIK
B5: TEMP PROJECT HIRE | E5: DAILY | F5: DLY
B6: CONSULTANT | E6: DAILY360 | F6: D36
B7: CONSULTANT EXTENDEE | E7: HALF-YEARLY | F7: HFY
A8: WORK AREA | B8: OFFICE | E8: HOURLY | F8: HOURLY
B9: OFFICE INTL | E9: QUARTERLY | F9: QTL
B10: OFFICE PROVINCIAL | E10: SEMI-MONTHLY | F10: SMT
B11: FIELD GMA | E11: WEEKLY | F11: WKL
B12: FIELD INTERNATIONAL | E12: MONTHLY | F12: MON
B13: FIELD PROVINCIAL | E13: MONTHLY13 | F13: M13
B14: PLANT | E14: MONTHLY14 | F14: M14
B15: PLANT INTERNATIONAL | E15: MONTHLY15 | F15: M15
B16: PLANT PROVINCIAL | E16: MONTHLY16 | F16: M16
A17: SHIFT CODE | B17: NPO (Non-Punching-Office)
B18: 001 - 7:30 – 16:30 | D18: MOTORIZED | E18: YES
B19: O02 - 7:00 – 16:00 | E19: NO
B20: O04 - 7:00 – 17:00
B21: O06 - 7:30 – 4:30 | D21: INCENTIVED | E21: YES
B22: O11 - 7:30 – 17:30 | E22: NO
B23: O23 - 8:00 – 6:00
B24: O24 - 8:00 – 17:00 | D24: ANNUAL BONUS | E24: YES2
B25: M01 - 6:00 – 14:00 | E25: YES5
B26: H40 - 7:00 – 17:00 | E26: NO
A27: WORK SCHEDULE | B27: COMPRESSED | D27: SPECIAL ALLOWANCE | E27: NO
B28: NON-COMPRESSED 1 | E28: HZ
B29: NON-COMPRESSED 2 | E29: PA
A30: SWIPING STATUS | B30: SWIPING
B31: NON-SWIPING | D31: SG | E31: SG 05
A32: JOB CLASS | B32: RANK & FILE | E32: SG 06
B33: SUPERVISORY | E33: SG 07
B34: ASSISTANT MANAGER | E34: SG 08
B35: KEY PERSONNEL | E35: SG 09
A36: MRI | E36: SG 10
B37: YEAR | E37: S1
B38: N/A | E38: S2
A39: TRANSPO ALLOWANCE | B39: YES | E39: S2-C
B40: PROBY | E40: S3
...

Sheet Responses
A1: Id | B1: Start time | C1: Completion time | D1: Email | E1: Name | F1: By proceeding with this form, you consent to the collection, generation, use, processing, storage and retention of your personal data by the Company for your application process. | G1: Full Name (First Name, Last Name) | H1: Date Form is Accomplished | I1: Position Applied For | J1: Unilab Division | K1: Expected Monthly Basic Salary | L1: Age | M1: Employment Status | N1: Experience | O1: Name of Current Employer | P1: Industry of Last Employer | Q1: Last Position Held | R1: Monthly Basic Salary | S1: Guaranteed Months Pay | T1: Other Guaranteed Bonuses (Received Annually) | U1: Amount of Guaranteed Bonuses (Received Annually) | V1: Allowances (Received Monthly) | W1: Allowances (Received Monthly)1 | X1: Other Allowances (Received Non-monthly; quarterly, semi-annual or annual basis ) | Y1: Amount of Other Allowances (Received Non-monthly; quarterly, semi-annual or annual basis ) | Z1: Fixed Non-Taxable Allowances (Received Monthly) | AA1: Amount of Fixed Non-Taxable Allowances (Received Monthly) | AB1: Fixed Non-Taxable Allowances (Received Annually) | AC1: Amount of Fixed Non-Taxable Allowances (Received Annually) | AD1: Profit Sharing | AE1: Total Incentives / Commission (Annual) | AF1: Total Incentives / Commission (Annual)1 | AG1: Other variable Pay (Annual) | AH1: Amount of Other variable Pay (Annual) | AI1: HMO Benefit Limit for Employee | AJ1: HMO Benefit Limit for Dependents | AK1: Dental | AL1: Medicine Reimbursement | AM1: Optical | AN1: Other Health Benefits | AO1: Optional/Vacation Leaves | AP1: Sick Leave | AQ1: Other Leaves | AR1: Life Insurance | AS1: Other Benefits you are receiving but not asked in this form | AT1: Car / Vehicle or Car Plan if received in cash | AU1: Cellular Phone | AV1: ACCEPTED (TA)
A2: 34 | B2: 46094.707 | C2: 46094.788 | D2: anonymous | F2: I agree | G2: First Name Last Name 1 | H2: 46094 | I2: R&D | K2: 120000 | M2: Currently unemployed | N2: More than 10 years of relevant work experience | O2: Metadiagnostics Inc., dba Metametrics Laboratory | P2: Pharmaceutical & Healthcare | Q2: Laboratory Manager | R2: 83530 | S2: 13th Month Pay | T2: N/A | U2: 83530 | V2: transportation-meal allowance/per diem allowance, hazard pay | W2: 5640 | X2: quarterly rice/grocery subsidy, annual medical reimbursement | Y2: 11000 | AD2: 0 | AE2: 10-12K lab head monthly incentive | AF2: 144000 | AG2: 14th and 15th month performance based-bonus | AH2: 167060 | AI2: 150,000 maximum benefit limit | AJ2: 0 | AK2: Dental services covered (employee) | AL2: P5,000 per year | AM2: included in the 150K limit | AN2: N/A | AO2: 7 days | AP2: 7 days, convertible to cash if unused | AQ2: N/A | AR2: P500,000 coverage (company paid) | AS2: Pag-ibig, SSS, and Philhealth
A3: 34 | B3: 46097.459 | C3: 46097.481 | D3: anonymous | F3: I agree | G3: First Name Last Name 2 | H3: 46097 | I3: External Affairs Specialist | K3: 55000 | M3: Currently with part-time work | N3: With 3 to 5 years of relevant work experience | O3: CMC Designs | P3: Marketing/Media / Publication | Q3: Digital Operations & Content Manager | R3: 45500 | S3: 13th Month Pay | T3: N/A | U3: 0 | V3: Communication Allowance | W3: 2500 | X3: N/A | Y3: 0 | AD3: 0 | AE3: N/A | AF3: 0 | AG3: Performance Based Bonus | AH3: 24735.56 | AI3: 100000 | AJ3: N/A | AK3: Basic dental services covered | AL3: 0 | AM3: 0 | AN3: 0 | AO3: 15 days, non-convertable to cash if unused | AP3: 10 days, non-convertable to cash if unused | AQ3: N/A | AR3: 0
A4: 34 | B4: 46104.41 | C4: 46104.412 | D4: anonymous | F4: I agree | G4: First Name Last Name 3 | H4: 46104 | I4: ASST. PRODUCT MANAGER | K4: 180000 | M4: Currently employed | N4: More than 10 years of relevant work experience | O4: BSV BIOSCIENCE PHILS. INC. | P4: Pharmaceutical & Healthcare | Q4: PRODUCT MANAGER | R4: 90000 | S4: 13th Month Pay | V4: 0 | W4: 0 | X4: 0 | Y4: 0 | AD4: 0 | AE4: Annual Incentives | AH4: 0 | AI4: 0 | AJ4: 0 | AK4: 0 | AL4: 0 | AM4: 0 | AN4: 0 | AO4: 0 | AP4: 0 | AQ4: 0 | AR4: 0
A5: 34 | B5: 46105.328 | C5: 46105.344 | D5: anonymous | F5: I agree | G5: First Name Last Name 4 | H5: 46105 | I5: CUSTOMER DEVELOPMENT SPECIALIST | K5: 45000 | M5: Currently unemployed | N5: With 6 to 10 years of relevant work experience | O5: RC EGG TRADING | P5: Consumer Goods | Q5: DISTRIBUTION MANAGER | R5: 45000 | S5: 12th Month Pay | T5: 25000-30000 CHRISTMAS BONUS | U5: 30000 | V5: N/A | W5: 0 | X5: NA | Y5: 0 | AD5: 0 | AE5: 180000 | AF5: 180000 | AG5: NA | AH5: 0
A6: 34 | B6: 46129.723 | C6: 46129.751 | D6: anonymous | F6: I agree | G6: First Name Last Name 5 | H6: 46129 | I6: CONTROLLERSHIP ANALYST | K6: 35000 | M6: Currently employed | N6: With less than 1 year of relevant work experience. | O6: HOMER DE JESUS | P6: Professional Services | Q6: ACCOUNTANT I | R6: 25000 | S6: 14th Month Pay | T6: Midyear Bonus | U6: 10000 | V6: Transportation Allowance, Meal Allowance, Communication Allowance | W6: 3600 | X6: Quarterly Rice Allowance | Y6: 2500 | AD6: 0 | AE6: n/a | AF6: 0 | AG6: n/a | AH6: 0 | AI6: 150,000 | AK6: Basic dental services covered (employee only) | AO6: 10 days | AP6: 10 days
A7: 39 | B7: 46202.589 | C7: 46202.602 | D7: anonymous | F7: I agree | G7: First Name Last Name 6 | H7: 46202 | I7: Trade Marketing Specialist | K7: 65000 | M7: Currently employed | N7: More than 10 years of relevant work experience | O7: All Year Home Products, Inc. | P7: Manufacturing | Q7: Trade Marketing Manager | R7: 60000 | S7: 12th Month Pay | T7: Year End Bonus (1 month Salary) | U7: 60000 | V7: Non Tax Allowance, Transpo Allowance and Other Allowance | W7: 25000 | X7: N/A | Y7: 0 | AD7: 0 | AE7: Management Incentive | AF7: 10000 | AG7: N/A | AH7: 0 | AI7: 130,000 accumulated benefit, including dependents. This is not an HMO plan; eligible medical expenses are reimbursable by the company. | AJ7: 130,000 accumulated benefit, including dependents. This is not an HMO plan; eligible medical expenses are reimbursable by the company. | AK7: 2000 | AL7: 20000 (included in the 130,00) | AM7: N/A | AN7: N/A | AO7: 12 days, which may be carried over to the following year if unused. | AP7: 12 days | AQ7: Birthday leave - 1 day and bereavement leave - 3 days | AR7: 1,000,000 (Company Paid) | AS7: Company Phone is provided, Service Car is provided, Uniform is provided | AT7: Montero GLS | AU7: Android Phone with 700 Plan
A8: 40 | B8: 46224.478 | C8: 46224.497 | D8: anonymous | F8: I agree | G8: First Name Last Name 7 | H8: 46224 | I8: Business Unit Finance Specialist | K8: 75000 | M8: Currently employed | N8: With 1 to 2 years of relevant work experience | O8: The Standard Hospitality Group | P8: Food & Beverage | Q8: Management Accounting Assistant Manager | R8: 56450 | S8: 13th Month Pay | T8: Midyear Performance Bonus | U8: 60000 | V8: De Minimis 3050, Mobile Allowance 500 | W8: 3550 | X8: N/A | Y8: 0 | AD8: 0 | AE8: N/A | AF8: 0 | AG8: 0 | AH8: 0 | AI8: 100,000 | AJ8: 0 | AK8: Basic dental services covered (employee only) | AL8: Up to ₱1,500 per year (employee only) | AM8: Up to ₱1,500 per year (employee only) | AN8: 0 | AO8: 15 days, not convertable to cash if unused | AP8: 15 days, convertable to cash if unused | AQ8: 0 | AR8: 0 | AS8: Mandatory Annual Physical Exam | AT8: 0 | AU8: 0
A9: 41 | B9: 46224.533 | C9: 46224.553 | D9: anonymous | F9: I agree | G9: First Name Last Name 8 | H9: 46224 | I9: Controllership Specialist | K9: 60000 | M9: Currently unemployed | N9: With 1 to 2 years of relevant work experience | O9: PwC Isla Lipana | P9: Banking & Finance, Insurance | Q9: Experienced Audit Associate | R9: 25000 | S9: 13th Month Pay | T9: N/A | U9: 0 | V9: Meal Allowance, Data Subsidy, Work from Home Allowance | W9: 1250 | X9: Annual Cash Gift | Y9: 1500 | AD9: 25000 | AE9: N/A | AF9: 0 | AG9: N/A | AH9: 0 | AI9: 110,000 | AJ9: 110,000 | AK9: 10,000 | AL9: Included in dental | AM9: Included in dental | AN9: N/A | AO9: 24 | AP9: Included in VL as multipurpose leave | AQ9: N/A | AR9: N/A | AS9: N/A | AT9: N/A | AU9: N/A
A10: 42 | B10: 46227.628 | C10: 46227.637 | D10: anonymous | F10: I agree | G10: First Name Last Name 9 | H10: 46227 | I10: Trade Execution Specialist | K10: 140000 | M10: Currently unemployed | N10: With 6 to 10 years of relevant work experience | O10: Mondelez Philippines, Inc. | P10: Consumer Goods | Q10: Retail Development Manager | R10: 85079.63 | S10: 13th Month Pay | T10: N/A | U10: 0 | V10: Meal Allowance = Daily field per diem (₱200/day; ₱400/day for outbase fieldwork beyond 50 km) ; Transportation Allowance = N/A – Business travel expenses were reimbursable based on company policy | W10: 6000 | X10: Quarterly Clothing Allowance | Y10: 8000 | AD10: 0 | AE10: Performance-based Sales Incentives (quarterly incentive program with payouts of up to ₱80,000 per quarter, or up to ₱320,000 annually, including overachievement incentives for exceeding targets and monthly Big Hit incentives) | AF10: 320000 | AG10: N/A | AH10: 0 | AI10: Employee covered; maximum benefit limit not recalled | AJ10: 1 dependent covered (mother); maximum benefit limit not recalled | AK10: Basic dental services covered (employee only) | AL10: N/A | AM10: ₱10,000 per year (employee only) | AN10: N/A | AO10: 15 days; up to 5 unused days may be carried over to the following year | AP10: 15 days; convertible to cash if unused | AQ10: N/A | AR10: N/A | AS10: Rice Allowance = Php 2,000 monthly | AT10: Toyota Vios | AU10: Php 2,000 Allowance per month
A11: 43 | B11: 46227.687 | C11: 46227.731 | D11: anonymous | F11: I agree | G11: First Name Last Name 10 | H11: 46227 | I11: Trade Execution Specialist / Key Accounts | K11: 90000 | M11: Currently employed | N11: With 6 to 10 years of relevant work experience | O11: Unilever | P11: Consumer Goods | Q11: Customer Development Executive | R11: 65000 | S11: 14th Month Pay | T11: Perfomance Based Bonus | U11: 200000 | V11: Gift Pack Allowance, Rice Subsidy, Meal Allowance, Incidentals, Housing Allowance, Car Wash, Gym Allowance | W11: 53200 | X11: Annual Medicine Allowance | Y11: 100000 | AD11: 0 | AE11: No profit sharing but matching of invested Unilever shares | AF11: 24000 | AG11: N/A | AH11: 0 | AI11: 250000 | AJ11: 160000 | AK11: basic dental benefits including dependents | AL11: 100000 | AM11: 3000 | AO11: 20 days, convertable to cash if unused | AP11: 90 days | AT11: Isuzu Dmax | AU11: cash for phone (worth 20k) with unli call, text, and data; ipad with unli data
A12: 44 | B12: 46229.965 | C12: 46229.976 | D12: anonymous | F12: I agree | G12: First Name Last Name 11 | H12: 46229 | I12: ECommerce Officer | K12: 110000 | M12: Currently employed | N12: With 3 to 5 years of relevant work experience | O12: WPP Media | P12: Marketing/Media / Publication | Q12: Senior Associate - ECommerce Planning | R12: 85000 | S12: 13th Month Pay | T12: N/A | U12: 0 | V12: 800 php Phone Allowance | W12: 0 | X12: N/A | Y12: 0 | AD12: 0 | AE12: N/A | AF12: 0 | AG12: N/A | AH12: 0 | AI12: 300000 | AJ12: 200000 | AM12: Up to 12,000 per year (x2 with dependent) | AN12: Medical reimbursements of PHP 15,000/year. Inclusive of PHP 12,500 Dental reimbursements. | AO12: 15 days | AP12: 12 days | AQ12: Birthday leave - 1 day, emergency leave - 3 days | AR12: ₱500,000 coverage (company-paid) | AS12: Retirement Benefit • Marriage Bonus • Baby Bonus • Funeral Assistance

Sheet Benefits
A1: CURRENT BENEFITS PACKAGE
A4: ID | B4: 34
A5: CANDIDATE'S NAME | B5: =VLOOKUP(B4,Responses!A:AU,7,0) -> First Name Last Name 1
A6: CURRENT POSITION | B6: =VLOOKUP(B4,Responses!A:AU,17,0) -> Laboratory Manager
A7: CURRENT EMPLOYER | B7: =VLOOKUP(B4,Responses!A:AU,15,0) -> Metadiagnostics Inc., dba Metametrics Laboratory
A9: BENEFITS | B9: DETAILS OF ENTITLEMENT
A10: HEALTH BENEFITS
A11: Hospitalization limit for employees | B11: =VLOOKUP(B4,Responses!A:AU,35,0) -> 150,000 maximum benefit limit
A12: Hospitalization limit for dependents | B12: =VLOOKUP(B4,Responses!A:AU,36,0) -> 0
A13: Medicine Reimbursement | B13: =VLOOKUP(B4,Responses!A:AU,38,0) -> P5,000 per year
A14: Dental | B14: =VLOOKUP(B4,Responses!A:AU,37,0) -> Dental services covered (employee)
A15: Optical | B15: =VLOOKUP(B4,Responses!A:AU,39,0) -> included in the 150K limit
A16: Other Health Benefits | B16: =VLOOKUP(B4,Responses!A:AU,40,0) -> N/A
A17: LEAVES
A18: Optional/Vacation Leaves | B18: =VLOOKUP(B4,Responses!A:AU,41,0) -> 7 days
A19: Sick Leave | B19: =VLOOKUP(B4,Responses!A:AU,42,0) -> 7 days, convertible to cash if unused
A20: Other Leaves | B20: =VLOOKUP(B4,Responses!A:AU,43,0) -> N/A
A21: TOOLS OF TRADE
A22: Car/Vehicle | B22: =VLOOKUP(B4,Responses!A:AU,46,0) -> 0
A23: Cellular Phone | B23: =VLOOKUP(B4,Responses!A:AU,47,0) -> 0
A24: INSURANCE PROGRAMS
A25: Life Insurance | B25: =VLOOKUP(B4,Responses!A:AU,44,0) -> P500,000 coverage (company paid)
A27: Other Benefits | B27: =VLOOKUP(B4,Responses!A:AU,45,0) -> Pag-ibig, SSS, and Philhealth

Sheet JO Regular
A1: Unilab, Inc.
A2: Job Offer Sheet - Compensation Package
C4: ID | D4: 35 | H4: Company: | I4: Unilab, Inc. | O4: Date of Processing | R4: =TODAY() -> 46247
A6: BASIC INFORMATION ABOUT THE CANDIDATE
A8: Candidate's Name | E8: =VLOOKUP(D4,Responses!A:AU,7,0) -> #N/A | O8: Salary Grade | R8: S2
A10: Position Title | E10: TRADE EXECUTION SPECIALIST | O10: Position Code
A12: Division/Department | E12: SALES AND CUSTOMER DEVELOMENT | O12: immediate Superior | R12: DON JOHNSON TORAYNO
A15: SUCCESS FACTORS INFO FOR ENCODING
B17: EMP STATUS | E17: PROBATIONARY | I17: Employment Status upon Hiring | N17: FREQUENCY | Q17: M15 | R17: # of Guaranteed Months
B18: WORK AREA | E18: OFFICE PROVINCIAL | I18: Assigned Work Area | N18: MOTORIZED | Q18: YES | R18: Eligibility to Company Car
B19: SHIFT CODE | E19: NPO (Non-Punching-Office) | I19: Assigned Shift Schedule | N19: INCENTIVIZED | Q19: YES | R19: Eligibility to Incentives
B20: WORK SCHEDULE | E20: COMPRESSED | I20: Assigned Work Schedule | N20: TRANSPO ALLOWANCE | Q20: N/A | R20: Eligibility to Transpo Allowance
B21: SWIPING STATUS | E21: NON-SWIPING | I21: Assigned Swiping Status | N21: ANNUAL BONUS | Q21: NO | R21: Eligibility to Annual Bonus
B22: JOB CLASS | E22: SUPERVISORY | I22: Job Classification | N22: SPECIAL ALLOWANCE | Q22: NO | R22: Eligibility to Hazard Pay/Pharmacist Allowance
A24: CANDIDATE'S WORK EXPERIENCE
B26: Employment Status | F26: =VLOOKUP(D4,Responses!A:AU,13,0) -> #N/A | O26: Name of Last Employer | P26: =IFERROR(IF(VLOOKUP(D4,Responses!A:AU,15,0)=0,"N/A",VLOOKUP(D4,Responses!A:AU,15,0)),"N/A") -> N/A
B28: Work Experience | F28: =VLOOKUP(D4,Responses!A:AU,14,0) -> #N/A | O28: Last Position Held | P28: =IFERROR(IF(VLOOKUP(D4,Responses!A:AU,17,0)=0,"N/A",VLOOKUP(D4,Responses!A:AU,17,0)),"N/A") -> N/A
A30: CASH COMPENSATION PACKAGE
A32: Components of Cash Compensation | H32: C U R R E N T | P32: P R O P O S E D
H33: Monthly | I33: Annual | K33: Remarks | P33: Monthly | Q33: Annual | T33: Remarks | X33: Current (Pro-rated) | Y33: Proposed (Prorated)
A34: FIXED COMPONENT (Guaranteed Cash)
A35: Monthly Basic Salary (MBS) | H35: =VLOOKUP(D4,Responses!A:AU,18,0) -> #N/A | I35: =H35*12 -> #N/A | Q35: =P35*12 -> 0 | X35: =$I$35*((13-$R$12)/12) -> #N/A | Y35: =$Q$35*((13-$R$12)/12) -> #VALUE!
A36: 13th Month Pay (1.00 x MBS) | I36: =H35 -> #N/A | Q36: =P35*1 -> 0 | T36: 13th month; prorated on first year | X36: =$I$36*((13-$R$12)/12) -> #N/A | Y36: =$Q$36*((13-$R$12)/12) -> #VALUE!
A37: Other Guaranteed Bonus/es | I37: =VLOOKUP(D4,Responses!A:AU,21,0) -> #N/A | K37: =IFERROR(IF(VLOOKUP(D4,Responses!A:AU,20,0)=0,"N/A",VLOOKUP(D4,Responses!A:AU,20,0)),"N/A") -> N/A | Q37: =P35*2 -> 0 | T37: 14th and 15th month | X37: =$I$37*((13-$R$12)/12) -> #N/A | Y37: =Q37/2 -> 0 | AA37: Fixed Taxable
A38: Allowance/s | I38: 25000 | K38: Non Tax Allowance, Transpo Allowance and Other Allowance | P38: =Q38/12 -> 2000 | Q38: =IF(Q20="YES", (275*90)+(2000*12), (2000*12) ) +IF(Q22="HZ",5280, IF(Q22="PA",3000,0)) -> 24000 | T38: Rice allowance : 2,000/month Transpo allowance : 90/day per work day | X38: =$I$38*((13-$R$12)/12) -> #VALUE! | Y38: =#REF!*((13-$R$12)/12) -> #REF! | AA38: =VLOOKUP(D4,Responses!A:AU,22,0) -> #N/A | AB38: =VLOOKUP(D4,Responses!A:AU,24,0) -> #N/A | AC38: =CONCATENATE(AA38,",",AB38) -> #N/A
A40: VARIABLE COMPONENT (Bonus/es) | AA40: Fixed Non Taxable
A41: Profit Share | I41: =VLOOKUP(D4,Responses!A:AU,30,0) -> #N/A | K41: Profit Share | Q41: =P35*1 -> 0 | T41: Entitlement to PS starts on year regularized | AA41: =VLOOKUP(D4,Responses!A:AU,26,0) -> #N/A | AB41: =VLOOKUP(D4,Responses!A:AU,28,0) -> #N/A | AC41: =CONCATENATE(AA41,",",AB41) -> #N/A
A42: Incentives/Commmission | I42: =VLOOKUP(D4,Responses!A:AU,32,0) -> #N/A | K42: =IFERROR(IF(VLOOKUP(D4,Responses!A:AU,31,0)=0,"N/A",VLOOKUP(D4,Responses!A:AU,31,0)),"N/A") -> N/A | Q42: 222000 | T42: incentives | X42: =$I$42*((13-$R$12)/12) -> #N/A | Y42: =$Q$42*((13-$R$12)/12) -> #VALUE!
A43: Performance-Based Bonuses | I43: =VLOOKUP(D4,Responses!A:AU,34,0) -> #N/A | K43: =IFERROR(IF(VLOOKUP(D4,Responses!A:AU,33,0)=0,"N/A",VLOOKUP(D4,Responses!A:AU,33,0)),"N/A") -> N/A | X43: =$I$43*((13-$R$12)/12) -> #N/A | Y43: =$Q$43*((13-$R$12)/12) -> #VALUE!
A44: GROSS COMPENSATION | H44: =SUM(H35:H38,H41:H43) -> #N/A | I44: =SUM(I35:J38,I41:J43) -> #N/A | P44: =SUM(P35:P38,P41:P43) -> 2000 | Q44: =SUM(Q35:S38,Q41:S43) -> 246000 | X44: =SUM(X35:X38,X41:X43) -> #N/A | Y44: =SUM(Y35:Y38,Y41:Y43) -> #VALUE!
P45: % DIFFERENCE IN PAY
P46: MONTHLY | Q46: ANNUAL
P47: =(P44-H44)/H44 -> #N/A | Q47: =(Q44-I44)/I44 -> #N/A
A50: You may refer to the attached for non-cash compensation/benefit package
A52: ANALYSIS ON EQUITY
A54: Internal Equity | H54: No comparators affected
A55: External Equity | H55: Between MIN and MID of market-derived salary structure for the level
A57: RECRUITMENT CONTACT | F57: VALIDATION/APPROVAL
F58: Prepared by: | J58: Endorsed by: | N58: Approved by: | Q58: Approved by: (as applicable)
F60: N ASENSI | J60: RMLEE | N60: MA LEE | Q60: RCL AGUAS
...

Sheet Options Regular
B1: (REGULAR HIRE) SALARY RECOMMENDATION OPTIONS
B2: CANDIDATE | C2: CURRENT PACKAGE | F2: UL EQUIVALENT | H2: OPTIONS | I2: Proposed Monthly Basic | J2: % Difference in Pay | L2: # of Affected Incumbents | M2: Remarks
B3: ='JO Regular'!E8 -> #N/A | C3: Monthly Basic | D3: Total Months Pay | F3: Monthly Basic | G3: Total Months Pay | J3: Monthly | K3: Annual
C4: ='JO Regular'!H35 -> #N/A | D4: 13 | F4: =(C4*D4)/G4 -> #N/A | G4: 15 | H4: Option 1 | I4: 67200 | J4: =F27 -> #N/A | K4: =G27 -> #N/A | L4: 8 | M4: Max of S2.
H5: Option 2 | I5: 70000 | J5: =H27 -> #N/A | K5: =I27 -> #N/A | L5: 9 | M5: Above max of S2
H6: Option 3 | I6: 73000 | J6: =J27 -> #N/A | K6: =K27 -> #N/A | L6: 9 | M6: Unilab equivalent of most recent salary
H7: Option 4 | J7: =L27 -> #N/A | K7: =M27 -> #N/A
B9: Components of Cash Compensation | C9: C U R R E N T | F9: OPTION 1 | H9: OPTION 2 | J9: OPTION 3 | L9: OPTION 4
C10: Monthly | D10: Annual | F10: Monthly | G10: Annual | H10: Monthly | I10: Annual | J10: Monthly | K10: Annual | L10: Monthly | M10: Annual
B11: FIXED COMPONENT (Guaranteed Cash)
B12: Monthly Basic Salary (MBS) | C12: ='JO Regular'!H35 -> #N/A | D12: ='JO Regular'!I35 -> #N/A | F12: =I4 -> 67200 | G12: =F12*12 -> 806400 | H12: =I5 -> 70000 | I12: =H12*12 -> 840000 | J12: =I6 -> 73000 | K12: =J12*12 -> 876000 | L12: =I7 -> 0 | M12: =L12*12 -> 0
B13: 13th Month Pay (1.00 x MBS) | C13: ='JO Regular'!H36 -> 0 | D13: ='JO Regular'!I36 -> #N/A | F13: ='JO Regular'!$P$36 -> 0 | G13: =F12 -> 67200 | H13: ='JO Regular'!$P$36 -> 0 | I13: =H12*1 -> 70000 | J13: ='JO Regular'!$P$36 -> 0 | K13: =J12*1 -> 73000 | L13: ='JO Regular'!$P$36 -> 0 | M13: =L12*1 -> 0
B14: Other Guaranteed Bonus/es | C14: ='JO Regular'!H37 -> 0 | D14: ='JO Regular'!I37 -> #N/A | F14: ='JO Regular'!$P$37 -> 0 | G14: =F12*2 -> 134400 | H14: ='JO Regular'!$P$37 -> 0 | I14: =H12*2 -> 140000 | J14: ='JO Regular'!$P$37 -> 0 | K14: =J12*2 -> 146000 | L14: ='JO Regular'!$P$37 -> 0 | M14: =L12*2 -> 0
B15: Allowances | C15: ='JO Regular'!H38 -> 0 | D15: ='JO Regular'!I38 -> 25000 | F15: ='JO Regular'!$P$38 -> 2000 | G15: ='JO Regular'!$Q$38 -> 24000 | H15: ='JO Regular'!$P$38 -> 2000 | I15: ='JO Regular'!$Q$38 -> 24000 | J15: ='JO Regular'!$P$38 -> 2000 | K15: ='JO Regular'!$Q$38 -> 24000 | L15: ='JO Regular'!$P$38 -> 2000 | M15: ='JO Regular'!$Q$38 -> 24000
B17: VARIABLE COMPONENT (Bonus/es)
B18: Profit Share | C18: ='JO Regular'!H41 -> 0 | D18: ='JO Regular'!I41 -> #N/A | F18: ='JO Regular'!$P$41 -> 0 | G18: =F12 -> 67200 | H18: ='JO Regular'!$P$41 -> 0 | I18: =H12 -> 70000 | J18: ='JO Regular'!$P$41 -> 0 | K18: =J12 -> 73000 | L18: ='JO Regular'!$P$41 -> 0 | M18: =L12 -> 0
B19: Incentives/Commmission | C19: ='JO Regular'!H42 -> 0 | D19: ='JO Regular'!I42 -> #N/A | F19: ='JO Regular'!$P$42 -> 0 | G19: ='JO Regular'!$Q$42 -> 222000 | H19: ='JO Regular'!$P$42 -> 0 | I19: ='JO Regular'!$Q$42 -> 222000 | J19: ='JO Regular'!$P$42 -> 0 | K19: ='JO Regular'!$Q$42 -> 222000 | L19: ='JO Regular'!$P$42 -> 0 | M19: ='JO Regular'!$Q$42 -> 222000
B20: Performance-Based Bonuses | C20: ='JO Regular'!H43 -> 0 | D20: ='JO Regular'!I43 -> #N/A | F20: ='JO Regular'!$P$43 -> 0 | G20: ='JO Regular'!$Q$43 -> 0 | H20: ='JO Regular'!$P$43 -> 0 | I20: ='JO Regular'!$Q$43 -> 0 | J20: ='JO Regular'!$P$43 -> 0 | K20: ='JO Regular'!$Q$43 -> 0 | L20: ='JO Regular'!$P$43 -> 0 | M20: ='JO Regular'!$Q$43 -> 0
B21: GROSS COMPENSATION | C21: =SUM(C12:C15,C18:C20) -> #N/A | D21: =SUM(D12:D15,D18:D20) -> #N/A | F21: =SUM(F11:F15,F18:F20) -> 69200 | G21: =SUM(G12:G15,G18:G20) -> 1321200 | H21: =SUM(H12:H15,H18:H20) -> 72000 | I21: =SUM(I12:I15,I18:I20) -> 1366000 | J21: =SUM(J12:J15,J18:J20) -> 75000 | K21: =SUM(K12:K15,K18:K20) -> 1414000 | L21: =SUM(L12:L15,L18:L20) -> 2000 | M21: =SUM(M12:M15,M18:M20) -> 246000
F24: % DIFFERENCE IN PAY
F25: OPTION 1 | H25: OPTION 2 | J25: OPTION 3 | L25: OPTION 4
F26: MONTHLY | G26: ANNUAL | H26: MONTHLY | I26: ANNUAL | J26: MONTHLY | K26: ANNUAL | L26: MONTHLY | M26: ANNUAL
F27: =(F21-C21)/C21 -> #N/A | G27: =(G21-D21)/D21 -> #N/A | H27: =(H21-C21)/C21 -> #N/A | I27: =(I21-D21)/D21 -> #N/A | J27: =(J21-C21)/C21 -> #N/A | K27: =(K21-D21)/D21 -> #N/A | L27: =(L21-C21)/C21 -> #N/A | M27: =(M21-D21)/D21 -> #N/A

Sheet CC Regular
A5: Name of Candidate: | B5: ='JO Regular'!E8 -> #N/A
A6: Position Considered for: | B6: ='JO Regular'!E10 -> TRADE EXECUTION SPECIALIST
A7: Salary Grade: | B7: ='JO Regular'!R8 -> S2
A8: Department/ Division: | B8: ='JO Regular'!E12 -> SALES AND CUSTOMER DEVELOMENT
A9: Company | B9: ='JO Regular'!I4 -> Unilab, Inc.
A10: PROPOSED PACKAGE
B12: Amount | C12: Schedule of Payout | D12: Conditions
A13: Monthly Base Pay | B13: ='JO Regular'!P35 -> 0 | C13: =IF(OR('JO Regular'!R8="AM",'JO Regular'!R8="S2-C",'JO Regular'!R8="S3-C",'JO Regular'!R8="S4-C",'JO Regular'!R8="S5-C"),"15th and end-of-month","10th and 25th of the month") -> 10th and 25th of the month
A15: Bonuses
A16: 13th Month | B16: 1 month | C16: 41228 | D16: The 13th month bonus shall be pro-rated on the first year and computed based on monthly salary at the time of payout.
A18: Bayanihan Bonuses | B18: half month | C18: 37605 | D18: =IF('JO Regular'!R8="AM", "Entitlement to the bonuses will commence after the employee has completed one (1) month of tenure. Bonuses shall be granted in full and computed based on the monthly salary at the time of payout.", "Entitlement to the bonuses will commence upon regularization. Bonuses shall be granted in full and computed based on the monthly salary at the time of payout.") -> Entitlement to the bonuses will commence upon regularization. Bonuses shall be granted in full and computed based on the monthly salary at the time of payout.
B19: half month | C19: 37302
B20: half month | C20: 37422
B21: half month | C21: 37514
A23: Profit Share | B23: Minimum of 1 month | C23: 41029 | D23: Profit share shall be pro-rated on the first year and computed based on actual business and individual performance, as well as job level and tenure. Entitlement shall begin on the applicable performance year when the new employee is regularized.
A25: Merit Rating Increase | C25: Annual pay-out; Effective January 1 (covering full year performance) | D25: Entitlement to Merit Rating Increase shall commence on the performance cycle when the new employee is regularized. Amount shall be computed based on actual business and individual performance, and job level. If hired and regularized within the same year, MRI will be pro-rated based on hire date.
A27: Transportation Allowance | B27: =IF('JO Regular'!R8="AM", "N/A", IF('JO Regular'!Q20="YES", "P90 per workday", IF('JO Regular'!Q20="PROBY", "P90 per workday, while on Probation", IF('JO Regular'!Q20="N/A","N/A",0) ) ) ) -> N/A | D27: =IF(B27="P90 per workday","-",IF(B27="P90 per workday, while on Probation","Provision of Transporation Allowance will stop upon regularization"," "))
A29: Tools of the Trade | B29: =IF('JO Regular'!Q18="YES","Company car based on job level/position (not necessarily brand new) with corresponsing gas allocation and other work tools such as computer and mobile phone. For ULCH, Provision of company car will commence upon regularization","N/A") -> Company car based on job level/position (not necessarily brand new) with corresponsing gas allocation and other work tools such as computer and mobile phone. For ULCH, Provision of company car will commence upon regularization | D29: =IF('JO Regular'!Q20="PROBY","Provision of company car will commence upon regularization"," ")
A31: Incentives | B31: =IF('JO Regular'!Q19="YES","Based on incentives mechanics discussed by the Division","N/A") -> Based on incentives mechanics discussed by the Division
A33: Performance Bonus | B33: =IF('JO Regular'!Q21="YES2", "Max of 2 months depending on individual performance and set mechanics of the Division", "N/A") -> N/A | D33: =IF('JO Regular'!Q21="YES2","Pro-rated if less than 1 year tenure; taxed. If hire date is on or after November 1, entitlement will be on the following year"," ")
A35: Remarks:
A38: The Job Offer and hiring of the candidate is subject to Management approval, passing the pre-employment medical exam, and results of the background check.
A41: Unilab Confidential. This material is intended for authorized UNILAB individuals only. It must not be reproduced in whole or in part, in any form, or by any means without formal agreement with or written consent from the Information Owner.
D44: Noted by:
D47: A CANSANAY
D48: Talent Acquisition Specialist
A52: I understand that the above is conditional upon successfully securing the relevant management approvals and on the Company being satisfied with the results of all pre-employment checks, including but not limited to the pre-employment medical exam, background and reference checks.
D54: Acknowledged by:
D58: Candidate's name/signature

Sheet JO Project
A1: =I4 -> Unilab, Inc.
A2: Job Offer Sheet - Compensation Package
C4: ID | D4: 21 | H4: Company: | I4: Unilab, Inc. | O4: Date of Processing | R4: =VLOOKUP(D4,Responses!A:AU,8,0) -> #N/A
A6: BASIC INFORMATION ABOUT THE CANDIDATE
A8: Candidate's Name | E8: =VLOOKUP(D4,Responses!A:AU,7,0) -> #N/A | O8: Salary Grade | R8: NR
A10: Position Title | E10: =VLOOKUP(D4,Responses!A:AU,9,0) -> #N/A | O10: Position Code
A12: Division/Department | E12: ESFG | O12: immediate Superior
A15: SUCCESS FACTORS INFO FOR ENCODING
B17: EMP STATUS | E17: TEMP PROJECT HIRE | I17: Employment Status upon Hiring | N17: FREQUENCY | Q17: M13 | R17: # of Guaranteed Months
B18: WORK AREA | E18: OFFICE | I18: Assigned Work Area | N18: MOTORIZED | Q18: NO | R18: Eligibility to Company Car
B19: SHIFT CODE | E19: O11 - 7:30 – 17:30 | I19: Assigned Shift Schedule | N19: INCENTIVIZED | Q19: NO | R19: Eligibility to Incentives
B20: WORK SCHEDULE | E20: COMPRESSED | I20: Assigned Work Schedule | N20: SPECIAL ALLOWANCE | Q20: NO | R20: Eligibility to Hazard Pay/Pharmacist Allowance
B21: SWIPING STATUS | E21: SWIPING | I21: Assigned Swiping Status
B22: JOB CLASS | E22: NON-REGULAR | I22: Job Classification
A25: CANDIDATE'S WORK EXPERIENCE
B27: Employment Status | F27: =VLOOKUP(D4,Responses!A:AU,13,0) -> #N/A | O27: Name of Last Employer | P27: =VLOOKUP(D4,Responses!A:AU,15,0) -> #N/A
B29: Work Experience | F29: =VLOOKUP(D4,Responses!A:AU,14,0) -> #N/A | O29: Last Position Held | P29: =VLOOKUP(D4,Responses!A:AU,17,0) -> #N/A
A31: CASH COMPENSATION PACKAGE
A33: Components of Cash Compensation | H33: C U R R E N T | P33: P R O P O S E D
H34: Monthly | I34: Annual | K34: Remarks | P34: Monthly | Q34: Annual | T34: Remarks | X34: Current (Pro-rated) | Y34: Proposed (Prorated)
A35: FIXED COMPONENT (Guaranteed Cash)
A36: Monthly Basic Salary (MBS) | H36: 40000 | I36: =H36*12 -> 480000 | P36: 60000 | Q36: =P36*12 -> 720000 | X36: =$I$36*((13-$R$12)/12) -> 520000 | Y36: =$Q$36*((13-$R$12)/12) -> 780000
A37: 13th Month Pay (1.00 x MBS) | I37: =IF(K37="12th Month Pay","", IF(K37="13th Month Pay",H36*1, IF(K37="14th Month Pay",H36*2, IF(K37="15th Month Pay",H36*3, IF(K37="16th Month Pay",H36*4,""))))) -> #N/A | K37: =VLOOKUP(D4,Responses!A:AU,19,0) -> #N/A | X37: =$I$37*((13-$R$12)/12) -> #N/A | Y37: =$Q$37*((13-$R$12)/12) -> 0
A38: Other Guaranteed Bonus/es | I38: =VLOOKUP(D4,Responses!A:AU,21,0) -> #N/A | K38: =VLOOKUP(D4,Responses!A:AU,20,0) -> #N/A | X38: =$I$38*((13-$R$12)/12) -> #N/A | Y38: =Q38/2 -> 0 | AA38: Fixed Taxable
A39: Allowance/s | H39: =VLOOKUP(D4,Responses!A:AU,23,0) -> #N/A | I39: =VLOOKUP(D4,Responses!A:AU,25,0) -> #N/A | K39: =AC39 -> #N/A | X39: =$I$39*((13-$R$12)/12) -> #N/A | Y39: =$Q$39*((13-$R$12)/12) -> 0 | AA39: =VLOOKUP(D4,Responses!A:AU,22,0) -> #N/A | AB39: =VLOOKUP(D4,Responses!A:AU,24,0) -> #N/A | AC39: =CONCATENATE(AA39,",",AB39) -> #N/A
A41: VARIABLE COMPONENT (Bonus/es) | AA41: Fixed Non Taxable
A42: Profit Share | I42: =VLOOKUP(D4,Responses!A:AU,30,0) -> #N/A | K42: Profit Share | AA42: =VLOOKUP(D4,Responses!A:AU,26,0) -> #N/A | AB42: =VLOOKUP(D4,Responses!A:AU,28,0) -> #N/A | AC42: =CONCATENATE(AA42,",",AB42) -> #N/A
A43: Incentives/Commmission | I43: =VLOOKUP(D4,Responses!A:AU,32,0) -> #N/A | K43: =VLOOKUP(D4,Responses!A:AU,31,0) -> #N/A | X43: =$I$43*((13-$R$12)/12) -> #N/A | Y43: =$Q$43*((13-$R$12)/12) -> 0
A44: Performance-Based Bonuses | I44: =VLOOKUP(D4,Responses!A:AU,34,0) -> #N/A | K44: =VLOOKUP(D4,Responses!A:AU,33,0) -> #N/A | X44: =$I$44*((13-$R$12)/12) -> #N/A | Y44: =$Q$44*((13-$R$12)/12) -> 0
A45: GROSS COMPENSATION | H45: =SUM(H36:H39,H42:H44) -> #N/A | I45: =SUM(I36:J39,I42:J44) -> #N/A | P45: =SUM(P36:P39,P42:P44) -> 60000 | Q45: =SUM(Q36:S39,Q42:S44) -> 720000 | X45: =SUM(X36:X39,X42:X44) -> #N/A | Y45: =SUM(Y36:Y39,Y42:Y44) -> 780000
P47: % DIFFERENCE IN PAY
P48: MONTHLY | R48: ANNUAL
P49: =(P45-H45)/H45 -> #N/A | R49: =(Q45-I45)/I45 -> #N/A
A52: You may refer to the attached for non-cash compensation/benefit package
A54: ANALYSIS ON EQUITY
A56: Internal Equity | H56: Will affect ___ of ___ comparators / No comparators affected
A57: External Equity | H57: [MIN / MID / MAX / Between MIN and MID / etc] of market-derived salary structure for the level
A59: RECRUITMENT CONTACT | F59: VALIDATION/APPROVAL
F60: Prepared by: | J60: Endorsed by: | N60: Approved by: | Q60: Approved by: (as applicble)
J62: RM Lee | N62: MA LEE | Q62: RCL AGUAS
...

Sheet Options Project
B1: (PROJECT HIRE) SALARY RECOMMENDATION OPTIONS
B2: CANDIDATE | C2: CURRENT PACKAGE | F2: UL EQUIVALENT | H2: OPTIONS | I2: Proposed Monthly Basic | J2: % Difference in Pay | L2: # of Affected Incumbents | M2: Remarks
B3: ='JO Regular'!E8 -> #N/A | C3: Monthly Basic | D3: Total Months Pay | F3: Monthly Basic | G3: Total Months Pay | J3: Monthly | K3: Annual
C4: ='JO Project'!H36 -> 40000 | D4: 13 | F4: =(C4*D4)/G4 -> 34666.667 | G4: 15 | H4: Option 1 | I4: 60000 | J4: =F27 -> #N/A | K4: =G27 -> #N/A
H5: Option 2 | I5: 65000 | J5: =H27 -> #N/A | K5: =I27 -> #N/A
H6: Option 3 | I6: 70000 | J6: =J27 -> #N/A | K6: =K27 -> #N/A
H7: Option 4 | I7: 75000 | J7: =L27 -> #N/A | K7: =M27 -> #N/A
B9: Components of Cash Compensation | C9: C U R R E N T | F9: OPTION 1 | H9: OPTION 2 | J9: OPTION 3 | L9: OPTION 4
C10: Monthly | D10: Annual | F10: Monthly | G10: Annual | H10: Monthly | I10: Annual | J10: Monthly | K10: Annual | L10: Monthly | M10: Annual
B11: FIXED COMPONENT (Guaranteed Cash)
B12: Monthly Basic Salary (MBS) | C12: ='JO Project'!H36 -> 40000 | D12: ='JO Project'!I36 -> 480000 | F12: =I4 -> 60000 | G12: =F12*12 -> 720000 | H12: =I5 -> 65000 | I12: =H12*12 -> 780000 | J12: =I6 -> 70000 | K12: =J12*12 -> 840000 | L12: =I7 -> 75000 | M12: =L12*12 -> 900000
B13: 13th Month Pay (1.00 x MBS) | C13: ='JO Project'!H37 -> 0 | D13: ='JO Project'!I37 -> #N/A | G13: =F12*1 -> 60000 | I13: =H12*1 -> 65000 | K13: =J12*1 -> 70000 | M13: =L12*1 -> 75000
B14: Other Guaranteed Bonus/es | C14: ='JO Project'!H38 -> 0 | D14: ='JO Project'!I38 -> #N/A | G14: =F12*2 -> 120000 | I14: =H12*2 -> 130000 | K14: =J12*2 -> 140000 | M14: =L12*2 -> 150000
B15: Allowance/s | C15: ='JO Project'!H39 -> #N/A | D15: ='JO Project'!I39 -> #N/A
B17: VARIABLE COMPONENT (Bonus/es)
B18: Profit Share | C18: ='JO Project'!H42 -> 0 | D18: ='JO Project'!I42 -> #N/A | G18: =F12*1 -> 60000 | I18: =H12*1 -> 65000 | K18: =J12*1 -> 70000 | M18: =L12*1 -> 75000
B19: Incentives/Commmission | C19: ='JO Project'!H43 -> 0 | D19: ='JO Project'!I43 -> #N/A | F19: ='JO Project'!P43 -> 0 | G19: ='JO Project'!Q43 -> 0 | H19: =F19 -> 0 | I19: =H19*12 -> 0 | J19: =H19 -> 0 | K19: =J19*12 -> 0 | L19: =J19 -> 0 | M19: =L19*12 -> 0
B20: Performance-Based Bonuses | C20: ='JO Project'!H44 -> 0 | D20: ='JO Project'!I44 -> #N/A | G20: ='JO Project'!Q44 -> 0 | H20: =F20 -> 0 | I20: =H20*12 -> 0 | J20: =H20 -> 0 | K20: =J20*12 -> 0 | L20: =J20 -> 0 | M20: =L20*12 -> 0
B21: GROSS COMPENSATION | C21: =SUM(C12:C15,C18:C20) -> #N/A | D21: =SUM(D12:D15,D18:D20) -> #N/A | F21: =SUM(F12:F15,F18:F20) -> 60000 | G21: =SUM(G12:G15,G18:G20) -> 960000 | H21: =SUM(H12:H15,H18:H20) -> 65000 | I21: =SUM(I12:I15,I18:I20) -> 1040000 | J21: =SUM(J12:J15,J18:J20) -> 70000 | K21: =SUM(K12:K15,K18:K20) -> 1120000 | L21: =SUM(L12:L15,L18:L20) -> 75000 | M21: =SUM(M12:M15,M18:M20) -> 1200000
F24: % DIFFERENCE IN PAY
F25: OPTION 1 | H25: OPTION 2 | J25: OPTION 3 | L25: OPTION 4
F26: MONTHLY | G26: ANNUAL | H26: MONTHLY | I26: ANNUAL | J26: MONTHLY | K26: ANNUAL | L26: MONTHLY | M26: ANNUAL
F27: =(F21-C21)/C21 -> #N/A | G27: =(G21-D21)/D21 -> #N/A | H27: =(H21-C21)/C21 -> #N/A | I27: =(I21-D21)/D21 -> #N/A | J27: =(J21-C21)/C21 -> #N/A | K27: =(K21-D21)/D21 -> #N/A | L27: =(L21-C21)/C21 -> #N/A | M27: =(M21-D21)/D21 -> #N/A

Sheet CC Project
A5: Name of Candidate: | B5: ='JO Project'!E8 -> #N/A
A6: Position Considered for: | B6: ='JO Project'!E10 -> #N/A
A7: Salary Grade: | B7: ='JO Project'!R8 -> NR
A8: Department/ Division: | B8: ='JO Project'!E12 -> ESFG
A9: Company: | B9: ='JO Project'!I4 -> Unilab, Inc.
A10: PROPOSED PACKAGE
B12: Amount | C12: Schedule of Payout | D12: Conditions
A13: Monthly Base Pay | B13: ='JO Project'!P36 -> 60000 | C13: 15th and end of the month
A15: Bonuses
A16: 13th Month | B16: 1 month | C16: 41258 | D16: The 13th month bonus shall be pro-rated on the first year and computed based on monthly salary at the time of payout.
A19: Remarks:
A22: The Job Offer and hiring of the candidate is subject to Management approval, passing the pre-employment medical exam, and results of the background check.
A25: Unilab Confidential. This material is intended for authorized UNILAB individuals only. It must not be reproduced in whole or in part, in any form, or by any means without formal agreement with or written consent from the Information Owner.
D28: Noted by:
D32: Talent Acquisition Specialist

Sheet JO Consultant
A1: =I4 -> Unilab, Inc.
A2: Job Offer Sheet - Compensation Package
C4: ID | D4: 22 | H4: Company: | I4: Unilab, Inc. | O4: Date of Processing | R4: =VLOOKUP(D4,Responses!A:AU,8,0) -> #N/A
A6: BASIC INFORMATION ABOUT THE CANDIDATE
A8: Candidate's Name | E8: =VLOOKUP(D4,Responses!A:AU,7,0) -> #N/A | O8: Salary Grade | R8: NR
A10: Position Title | E10: =VLOOKUP(D4,Responses!A:AU,9,0) -> #N/A | O10: Position Code
A12: Division/Department | E12: ESFG | O12: immediate Superior
A15: SUCCESS FACTORS INFO FOR ENCODING
B17: EMP STATUS | E17: CONSULTANT | I17: Employment Status upon Hiring | N17: FREQUENCY | Q17: MON | R17: # of Guaranteed Months
B18: WORK AREA | E18: OFFICE | I18: Assigned Work Area | N18: MOTORIZED | Q18: NO | R18: Eligibility to Company Car
B19: SHIFT CODE | E19: NPO (Non-Punching-Office) | I19: Assigned Shift Schedule | N19: INCENTIVIZED | Q19: NO | R19: Eligibility to Incentives
B20: WORK SCHEDULE | E20: COMPRESSED | I20: Assigned Work Schedule | N20: ANNUAL BONUS | Q20: NO | R20: Eligibility to Annual Bonus
B21: SWIPING STATUS | E21: NON-SWIPING | I21: Assigned Swiping Status
B22: JOB CLASS | E22: NON-REGULAR | I22: Job Classification
A24: CANDIDATE'S WORK EXPERIENCE
B26: Employment Status | F26: =VLOOKUP(D4,Responses!A:AU,13,0) -> #N/A | O26: Name of Last Employer | P26: =VLOOKUP(D4,Responses!A:AU,15,0) -> #N/A
B28: Work Experience | F28: =VLOOKUP(D4,Responses!A:AU,14,0) -> #N/A | O28: Last Position Held | P28: =VLOOKUP(D4,Responses!A:AU,17,0) -> #N/A
A30: CASH COMPENSATION PACKAGE
A32: Components of Cash Compensation | H32: C U R R E N T | P32: P R O P O S E D
H33: Monthly | I33: Annual | K33: Remarks | P33: Monthly | Q33: Annual | T33: Remarks
A34: FIXED COMPONENT (Guaranteed Cash)
A35: Monthly Basic Salary (MBS) | H35: =VLOOKUP(D4,Responses!A:AU,18,0) -> #N/A | I35: =H35*12 -> #N/A | P35: 60000 | Q35: =P35*12 -> 720000
A36: 13th Month Pay (1.00 x MBS) | I36: =IF(K36="12th Month Pay","", IF(K36="13th Month Pay",H35*1, IF(K36="14th Month Pay",H35*2, IF(K36="15th Month Pay",H35*3, IF(K36="16th Month Pay",H35*4,""))))) -> #N/A | K36: =VLOOKUP(D4,Responses!A:AU,19,0) -> #N/A | T36: Not entitled to 13th month
A37: Other Guaranteed Bonus/es | I37: =VLOOKUP(D4,Responses!A:AU,21,0) -> #N/A | K37: =VLOOKUP(D4,Responses!A:AU,20,0) -> #N/A
A38: Allowance/s | H38: =VLOOKUP(D4,Responses!A:AU,23,0) -> #N/A | I38: =VLOOKUP(D4,Responses!A:AU,25,0) -> #N/A | K38: =AC38 -> #N/A | AA38: =VLOOKUP(D4,Responses!A:AU,22,0) -> #N/A | AB38: =VLOOKUP(D4,Responses!A:AU,24,0) -> #N/A | AC38: =CONCATENATE(AA38,",",AB38) -> #N/A
A40: VARIABLE COMPONENT (Bonus/es)
A41: Profit Share | AA41: Fixed Non Taxable
A42: Incentives/Commmission | I42: =H42*12 -> 0 | AA42: =VLOOKUP(D4,Responses!A:AU,26,0) -> #N/A | AB42: =VLOOKUP(D4,Responses!A:AU,28,0) -> #N/A | AC42: =CONCATENATE(AA42,",",AB42) -> #N/A
A43: Performance-Based Bonuses
A44: GROSS COMPENSATION | H44: =SUM(H35:H38,H36:H43) -> #N/A | I44: =SUM(I35:J38,I41:J43) -> #N/A | P44: =SUM(P35:P38,P41:P43) -> 60000 | Q44: =SUM(Q35:S38,Q41:S43) -> 720000
P47: % DIFFERENCE
P48: MONTHLY | R48: ANNUAL
P49: =(P44-H44)/H44 -> #N/A | R49: =(Q44-I44)/I44 -> #N/A
A53: RECRUITMENT CONTACT | F53: VALIDATION/APPROVAL
F54: Prepared by: | J54: Endorsed by:
J56: RM Lee
F57: Talent Acquisition Specialist | J57: Talent Acquisition Head
W58: v.12.2025

Sheet CC Consultant
A5: Name of Candidate: | B5: ='JO Consultant'!E8 -> #N/A
A6: Position Considered for: | B6: ='JO Consultant'!E10 -> #N/A
A7: Salary Grade: | B7: ='JO Consultant'!R8 -> NR
A8: Department/ Division: | B8: ='JO Consultant'!E12 -> ESFG
A9: Company: | B9: ='JO Consultant'!I4 -> Unilab, Inc.
A10: PROPOSED PACKAGE
B12: Amount | C12: Schedule of Payout | D12: Conditions
A13: Professional Fee | B13: ='JO Consultant'!P35 -> 60000 | C13: 15th and end of the month
A16: Remarks:
A19: The Job Offer and hiring of the candidate is subject to Management approval, passing the pre-employment medical exam, and results of the background check.
A22: Unilab Confidential. This material is intended for authorized UNILAB individuals only. It must not be reproduced in whole or in part, in any form, or by any means without formal agreement with or written consent from the Information Owner.
D25: Noted by:
D28: Talent Acquisition Specialist
